<robot name="servo">
    <link name="left_hip">
      <visual>
        <origin rpy="0 0 0" xyz="0 0 0" />
        <geometry>
          <mesh filename="package://servo/meshes/LeftHip_V15.stl" scale="0.001 0.001 0.001" />
        </geometry>
        <material name="yellow">
            <color rgba="0.98 0.90 0.04 1"/>
        </material>
      </visual>
    </link>

    <link name="left_front_yaw_servo_base">
      <visual>
        <origin xyz="0 0 0"/>
        <geometry>
          <mesh filename="package://servo/meshes/Servo.stl"/>
        </geometry>
        <material name="dark_grey">
            <color rgba="0.1 0.1 0.1 1"/>
        </material>
      </visual>
    </link>

    <link name="left_front_pitch_servo_base">
      <visual>
        [<origin xyz="0 0 0"/>
        <geometry>
          <mesh filename="package://servo/meshes/Servo.stl"/>
        </geometry>
        <material name="dark_grey"/>
      </visual>
    </link>

    <link name="left_front_yaw_servo_horn">
      <visual>
        <origin xyz="0 0 0" />
        <geometry>
          <mesh filename="package://servo/meshes/ServoHorn.stl"/>
        </geometry>
        <material name="dark_grey"/>
      </visual>
    </link>

    <link name="left_front_pitch_servo_horn">
      <visual>
        <origin xyz="0 0 0" />
        <geometry>
          <mesh filename="package://servo/meshes/ServoHorn.stl"/>
        </geometry>
        <material name="dark_grey"/>
      </visual>
    </link>

    <joint name="swivel" type="continuous">
      <origin rpy="3.1415927 0 -1.57079632679" xyz="-0.01035 0 0.0292" />
      <axis xyz="0 0 -1" />
      <parent link="left_front_yaw_servo_base"/>
      <child link="left_front_yaw_servo_horn"/>
    </joint>

    <joint name="left_front_pitch_swivel" type="continuous">
      <origin rpy="3.1415927 0 -1.57079632679" xyz="-0.01035 0 0.0292" />
      <axis xyz="0 0 -1" />
      <parent link="left_front_pitch_servo_base"/>
      <child link="left_front_pitch_servo_horn"/>
    </joint>

    <joint name="hip_yaw_servo" type="fixed">
      <origin rpy="0 0 0" xyz="0 -0.00995 0"/>
      <parent link="left_hip"/>
      <child link="left_front_yaw_servo_base"/>
    </joint>

    <joint name="hip_pitch_servo" type="fixed">
      <origin rpy="0 -1.57079632679 3.1415927" xyz="-0.00991 0.01295 0.001005" />
      <parent link="left_hip"/>
      <child link="left_front_pitch_servo_base"/>
    </joint>
</robot>
